Workbook

Sheet CLIENTE
A1: NOME_FANTASIA | B1: RAZÃO_SOCIAL | C1: CPF_CNPJ | D1: ESTADO | E1: TELEFONE | F1: E-MAIL
A4: ASSEMBLEIA LEGISLATIVA DO ESTADO DO CEARÁ | B4: ASSEMBLEIA LEGISLATIVA DO ESTADO DO CEARÁ | C4: 06.750.525/0001-20 | D4: CEARÁ | E4: (85) 99659-5679 | F4: jessika.sato@al.ce.gov.br infracoti@al.ce.gov.br
A5: COMANDO DA 10a REGIAO MILITAR | B5: COMANDO DA 10a REGIAO MILITAR | C5: 09.560.963/0001-14 | D5: CEARÁ | E5: (85) 3255-1648 | F5: cpl10rm@gmail.com
A6: COLEGIO MILITAR DE FORTALEZA | B6: CMFOR | C6: 10.216.602/0001-34 | D6: CEARÁ | E6: (85) 8535-3737 | F6: informatica@cmf.eb.mil.br
A7: ESCOLA DE APRENDIZEM DE MARINHEIROS DO CEARÁ | B7: ESCOLA DE APRENDIZEM DE MARINHEIROS DO CEARÁ | C7: 00.394.502/0116-93 | D7: CEARÁ | E7: (85)3288-4734 | F7: eloy.lima@marinha.mil.br gleidson@marinha.mil.br
A8: UNIVERSIDADE FEDERAL DO CEARÁ | B8: UNIVERSIDADE FEDERAL DO CEARÁ | C8: 07.272.636/0001-31 | D8: CEARÁ | E8: (85) 3366-7377 / 7378 | F8: dgcac@proplad.ufc.br marcosb@ufc.br
A9: INSTITUTO FEDERAL DE EDUCAÇÃO E TECNOLOGIA - IFCE CAMOCIM | B9: INSTITUTO FEDERAL DE EDUCAÇÃO E TECNOLOGIA - IFCE CAMOCIM | C9: 10.744.098/0024-31 | D9: CEARÁ | E9: (88) 9623-2025 | F9: yara.cristina@ifce.edu.br celestina@ifce.edu.br
A10: INSTITUTO FEDERAL DE EDUCAÇÃO E TECNOLOGIA - IFCE CAUCAIA | B10: INSTITUTO FEDERAL DE EDUCAÇÃO E TECNOLOGIA - IFCE CAUCAIA | C10: 10.744.098/0023-50 | D10: CEARÁ | E10: (85) 9106-5665 | F10: contratos.caucaia@ifce.edu.br
A11: INSTITUTO FEDERAL DE EDUCAÇÃO E TECNOLOGIA - IFCE ITAPIPOCA | B11: INSTITUTO FEDERAL DE EDUCAÇÃO E TECNOLOGIA - IFCE ITAPIPOCA | C11: 10.744.098/0028-65 | D11: CEARÁ | E11: (85) 9423-4521 | F11: assdap@ifce.edu.br, Nathalia.sousa@ifce.edu.br
A12: INSTITUTO FEDERAL DE EDUCAÇÃO E TECNOLOGIA - IFCE PARACURU | B12: INSTITUTO FEDERAL DE EDUCAÇÃO E TECNOLOGIA - IFCE PARACURU | C12: 10.744.098/0029-46 | D12: CEARÁ | E12: (85) 3401-2442 ou (85) 98193-2171 | F12: sac@paracuru.ifce.edu.br, marcelo.silva@ifce.edu.br
A13: INSTITUTO FEDERAL DE EDUCAÇÃO E TECNOLOGIA - IFCE JUAZEIRO DO NORTE | B13: INSTITUTO FEDERAL DE EDUCAÇÃO E TECNOLOGIA - IFCE JUAZEIRO DO NORTE | C13: 10.744.098/0005-79 | D13: CEARÁ | E13: (88) 2101-5305 | F13: cti.juazeiro@ifce.edu.br, isaacbrigido@ifce.edu.br, dap.jua@ifce.edu.br
A14: MINISTÉRIO DA AGRICULTURA E PECUÁRIA/SUPERINTENDÊNCIA FEDERAL DE AGRICULTURA E PECUÁRIA NO PARANÁ (SFA-PR/MAPA) | B14: MINISTÉRIO DA AGRICULTURA E PECUÁRIA/SUPERINTENDÊNCIA FEDERAL DE AGRICULTURA E PECUÁRIA NO PARANÁ (SFA-PR/MAPA) | C14: 01.628.251/0001-88 | D14: PARANÁ | E14: (48) 98410-7584 ou (41) 9272-1569 | F14: alex.borges@agro.gov.br, jair.matos@agro.gov.br
... A54: SEMCAS | B54: SECRETARIA MUNICIPAL DA CRIANÇA E ASSISTÊNCIA SOCIAL | C54: 06.307.102/0001-30 | D54: MARANHÃO | E54: (98) 99158-0854 | F54: semcas@saoluis.ma.gov.br
A55: PREFEITURA MUNICIPAL DE ARACATI - CASA CIVIL | B55: PREFEITURA MUNICIPAL DE ARACATI - CASA CIVIL | C55: 07.684.756/0001-46 | D55: CEARÁ | F55: julio-juca@hotmail.com, TITTO.SOL@aracati.ce.gov.br>
A56: PREF. MUNICIPAL DE CANINDE - AGRICULTURA | B56: PREFEITURA MUNICIPAL DE CANINDE | C56: 07.963.259/0001-87 | D56: CEARÁ | E56: (85) 8542-1298 | F56: Agricultura.Canindece@gmail.com
A57: PREFEITURA MUNICIPAL DE ARACATI - SEGURANÇA CIDADÃ | B57: PREFEITURA MUNICIPAL DE ARACATI - SEGURANÇA CIDADÃ | C57: 07.684.756/0001-46 | D57: CEARÁ | F57: TITTO.SOL@aracati.ce.gov.br, ARACATISEGURANCA@gmail.com
A58: PREFEITURA MUNICIPAL DE ARACATI - SEGURANÇA CIDADÃ | B58: PREFEITURA MUNICIPAL DE ARACATI - SEGURANÇA CIDADÃ | C58: 07.684.756/0001-46 | D58: CEARÁ | F58: TITTO.SOL@aracati.ce.gov.br, ARACATISEGURANCA@gmail.com
A59: MARANGUAPE - PREFEITURA MUNICIPAL DE MARANGUAPE | B59: PREFEITURA MUNICIPAL DE MARANGUAPE - GABINETE | C59: 07.963.051/0001-68 | D59: CEARÁ | E59: (85) 3369-9101 | F59: gabfinan.mpe@gmail.com
A60: PREFEITURA MUNICIPAL DE MOCOCA | B60: PREFEITURA MUNICIPAL DE MOCOCA | C60: 44.763.928/0001-01 | D60: SÃO PAULO | E60: (19) 3656-9800 | F60: financeiro@mococa.sp.gov.br
A61: PREFEITURA MUNICIPAL DE TIANGUA - SAUDE | B61: PREFEITURA MUNICIPAL DE TIANGUA - SAUDE | C61: 07.735.178/0001-20 | D61: CEARÁ | E61: (85) 3671-2288 / (85) 3671-2888 | F61: licitacao@tiangua.ce.gov.br
A62: PREF. MUNICIPAL DE ARACATI - DESENVOLVIMENTO SOCIAL | B62: PREF. MUNICIPAL DE ARACATI - DESENVOLVIMENTO SOCIAL | C62: 07.684.756/0001-46 | D62: CEARÁ | F62: assistenciasocialfinanceiro4@gmail.com assistenciasocialfinanceiro@gmail.com, TITTO.SOL@aracati.ce.gov.br
A63: MARANGUAPE - PREFEITURA MUNICIPAL DE MARANGUAPE | B63: PREFEITURA MUNICIPAL DE MARANGUAPE - SAUDE | C63: 07.963.051/0001-68 | D63: CEARÁ | E63: (85) 3369-9101 | F63: ADMSAUDEPMM@gmail.com
A64: MARANGUAPE - PREFEITURA MUNICIPAL DE MARANGUAPE | B64: PREFEITURA MUNICIPAL DE MARANGUAPE - SAFIN | C64: 07.963.051/0001-68 | D64: CEARÁ | E64: (85) 3369-9101 | F64: maranguapesafinfin@gmail.com
A65: PREF. MUNICIPAL DE ARACATI - CONTROLADORIA | B65: PREF. MUNICIPAL DE ARACATI - CONTROLADORIA | C65: 07.684.756/0001-46 | D65: CEARÁ | F65: controladoria@aracati.ce.gov.br>, TITTO.SOL@aracati.ce.gov.br
A66: PREFEITURA MUNICIPAL DE ITAREMA - SAUDE | B66: PREFEITURA MUNICIPAL DE ITAREMA - SAUDE | C66: 07.663.941/0001-54 | D66: CEARÁ | E66: (88) 3667-1133 / 3667-1340 | F66: compras@itarema.ce.gov.br, setordecomprasitarema@gmail.com, comprasitarema@gmail.com.br, comprasitarema@gmail.com.gov.br
A67: PREFEITURA MUNICIPAL DE ACOPIARA - PROCURADORIA | B67: PREFEITURA MUNICIPAL DE ACOPIARA - PROCURADORIA | C67: 07.847.379/0001-19 | D67: CEARÁ | E67: (88) 3565-1999 | F67: prefeitura@acopiara.ce.gov.br, pedroaarolim@hotmail.com, procuradoria@acopiara.ce.gov.br
A68: MARANGUAPE - PREFEITURA MUNICIPAL DE MARANGUAPE | B68: PREFEITURA MUNICIPAL DE MARANGUAPE - SEJUV | C68: 07.963.051/0001-68 | D68: CEARÁ | E68: (85) 3369-9101 | F68: Sejuv.pmm@hotmail.com
A69: MARANGUAPE - PREFEITURA MUNICIPAL DE MARANGUAPE | B69: PREFEITURA MUNICIPAL DE MARANGUAPE - TRAB ASSIST SOCIAL | C69: 07.963.051/0001-68 | D69: CEARÁ | E69: (85) 3369-9101 | F69: financeiro.stds@gmail.com
A70: MARANGUAPE - PREFEITURA MUNICIPAL DE MARANGUAPE | B70: PREFEITURA MUNICIPAL DE MARANGUAPE - TRAB ASSIST SOCIAL | C70: 07.963.051/0001-68 | D70: CEARÁ | E70: (85) 3369-9101 | F70: financeiro.stds@gmail.com
A71: PREFEITURA MUNICIPAL DE ACOPIARA - SAÚDE | B71: PREFEITURA MUNICIPAL DE ACOPIARA - SAÚDE | C71: 07.847.379/0001-19 | D71: CEARÁ | E71: (88) 3565-1999 | F71: prefeitura@acopiara.ce.gov.br, pedroaarolim@hotmail.com, saude@acopiara.ce.gov.br
A72: PREFEITURA MUNICIPAL DE ACOPIARA - TRANSPORTE E LOGISTICA | B72: PREFEITURA MUNICIPAL DE ACOPIARA - TRANSPORTE E LOGISTICA | C72: 07.847.379/0001-19 | D72: CEARÁ | E72: (88) 3565-1999 | F72: prefeitura@acopiara.ce.gov.br, pedroaarolim@hotmail.com, sttrans@acopiara.ce.gov.br
A73: PREFEITURA MUNICIPAL DE ACOPIARA - TRABALHO E DESENVOLVIMENTO SOCIAL | B73: PREFEITURA MUNICIPAL DE ACOPIARA - TRABALHO E DESENVOLVIMENTO SOCIAL | C73: 07.847.379/0001-19 | D73: CEARÁ | E73: (88) 3565-1999 | F73: prefeitura@acopiara.ce.gov.br, pedroaarolim@hotmail.com, stds@acopiara.ce.gov.br
A74: PREFEITURA MUNICIPAL DE ACOPIARA - TRABALHO E DESENVOLVIMENTO SOCIAL - PROGRAMAS | B74: PREFEITURA MUNICIPAL DE ACOPIARA - TRABALHO E DESENVOLVIMENTO SOCIAL - PROGRAMAS | C74: 07.847.379/0001-19 | D74: CEARÁ | E74: (88) 3565-1999 | F74: prefeitura@acopiara.ce.gov.br, pedroaarolim@hotmail.com, stds@acopiara.ce.gov.br
A75: SECRETARIA DO TRABALHO DO ESTADO DO CEARÁ - SET | B75: SECRETARIA DO TRABALHO DO ESTADO DO CEARÁ - SET | C75: 49.921.771/0001-00 | D75: CEARÁ | E75: (85) 3376-1100 | F75: simone.teles@trabalho.ce.gov.br jidlafe.rodrigues@trabalho.ce.gov.br, carlos.cesar@trabalho.ce.gov.br
A76: PREFEITURA MUNICIPAL DE PALMACIA - FUNDO MUNICIPAL DE ASSISTENCIA SOCIAL | B76: PREFEITURA MUNICIPAL DE PALMACIA - FUNDO MUNICIPAL DE ASSISTENCIA SOCIAL | C76: 07.711.666/0001-05 | D76: CEARÁ | E76: (85) 3924-6903 | F76: assistencia@palmacia.ce.gov.br, controladoria@palmacia.ce.gov.br, matheusgomeschagas@gmail.com
A77: PREFEITURA MUNICIPAL DE PALMACIA - EDUCAÇÃO | B77: PREFEITURA MUNICIPAL DE PALMACIA - EDUCAÇÃO | C77: 07.711.666/0001-05 | D77: CEARÁ | E77: (85) 3924-6901 / (85) 3924-6901 | F77: sme@palmacia.ce.gov.br, controladoria@palmacia.ce.gov.br, matheusgomeschagas@gmail.com
... A82: PREFEITURA MUNICIPAL DE PALMACIA - FINANÇAS | B82: PREFEITURA MUNICIPAL DE PALMACIA - FINANÇAS | C82: 07.711.666/0001-05 | D82: CEARÁ | E82: (85) 3924-6907 / (85) 3924-6907 | F82: matheusgomeschagas@gmail.com, controladoria@palmacia.ce.gov.br, smefinanca@palmacia.ce.gov.br
A83: PREFEITURA MUNICIPAL DE ARACATI - DESENVOLVIMENTO AGRÁRIO | B83: PREFEITURA MUNICIPAL DE ARACATI - DESENVOLVIMENTO AGRÁRIO | C83: 07.684.756/0001-46 | D83: CEARÁ
A84: PREFEITURA MUNICIPAL DE PALMACIA - OBRAS E MEIO AMBIENTE | B84: PREFEITURA MUNICIPAL DE PALMACIA - OBRAS E MEIO AMBIENTE | C84: 07.711.666/0001-05 | D84: CEARÁ | E84: (85) 3924-6907/ (85) 3924-6907 | F84: obras@palmacia.ce.gov.br, controladoria@palmacia.ce.gov.br, matheusgomeschagas@gmail.com
A85: PREFEITURA MUNICIPAL DE PALMACIA - SAÚDE | B85: PREFEITURA MUNICIPAL DE PALMACIA - SAÚDE | C85: 07.711.666/0001-05 | D85: CEARÁ | E85: (85) 9.9110-5699 / (85) 3924-6909 | F85: saude@palmacia.ce.gov.br, controladoria@palmacia.ce.gov.br, matheusgomeschagas@gmail.com
...

Sheet CONTRATOS
A1: ID | B1: APELIDO_CONTRATO | C1: NUMERO_CONTRATO | D1: ANTIGO_CONTRATO | E1: TIPO_CONTRATO | F1: STATUS_CONTRATO | G1: CONTRATADO | H1: CONTRATANTE | I1: OBJETO_DO_CONTRATO
A4: 3 | B4: ALECE | C4: 97-2025 | E4: LICITAÇÃO | F4: EM ANDAMENTO | G4: ALUCOM | H4: ASSEMBLEIA LEGISLATIVA DO ESTADO DO CEARÁ | I4: O objeto do presente instrumento é LOCAGOES DE MAQUINARIOS DE INFORMATICA COM INSTALAGAO, MANUTENGAOQ, SUPORTE E GESTAO DO AMBIENTE DE TI, E EXECUGAO , CONTINUADA DE ATIVIDADES REFERENTES A INCIDENTES E SOLICITAGOES DE SERVIGOS, COM SUPORTE, ASSISTENCIA TECNICA E DISPONIBILIZACAO DE CENTRAL DE SERVICOS, nas condições estabelecidas neste contrato e no Termo de Referéncia do edital e na proposta do CONTRATADO.
A5: 4 | B5: 10a REGIAO MILITAR | C5: 002/2024 | E5: LICITAÇÃO | F5: EM ANDAMENTO | G5: ALUCOM | H5: COMANDO DA 10a REGIAO MILITAR | I5: .O objeto do presente instrumento é a Contrataçao de soluçao de tecnologia da informaçao e comunicaçao de serviço de Outsourcing de impressao, por Sistema de Registro de Preços (SRP), com fornecimento de suprimentos, peças de reposiçao e manutençao, para equipamentos alocados nos diversos setores, do Comando da 10a Regiao Militar, CS/10 e SRO/10, que serao prestados nas condiçoes estabelecidas no Termo de Referencia, anexo do Edital
A6: 5 | B6: CMFOR | C6: 006/2023-SALC/CMF | E6: LICITAÇÃO | F6: EM ANDAMENTO | G6: ALUCOM | H6: COLEGIO MILITAR DE FORTALEZA | I6: O objeto do presente instrumento é a escolha da proposta mais vantajosa para a contratação de solução de tecnologia da informação e comunicação, de serviços comuns e continuados sem dedicação exclusiva de mão-de-obra, de impressão corporativa - outsourcing de impressão - modalidade franquia mensal de páginas mais excedente, sem fornecimento de papel; com fornecimento e disponibilidade, nas dependências da CONTRATANTE, de equipamentos de impressão corporativa em regime de comodato, para atender ao Colégio Militar de Fortaleza; conforme condições, quantidades e exigências estabelecidas neste instrumento e seus anexos.
A7: 6 | B7: ESCOLA DE APRENDIZEM DE MARINHEIROS DO CEARÁ | C7: 83601/2024-007/00 | E7: LICITAÇÃO | F7: EM ANDAMENTO | G7: ALUCOM | H7: ESCOLA DE APRENDIZEM DE MARINHEIROS DO CEARÁ | I7: O objeto do presente instrumento é a contratação de solução de tecnologia da informação e comunicação de serviço de Outsourcing de impressão, por Sistema de Registro de Preços (SRP), com fornecimento de suprimentos, peças de reposição e manutenção, para equipamentos alocados nos diversos setores da Escola de Aprendizes-Marinheiros do Ceará (EAMCE), que serão
A8: 7 | B8: UFC | C8: 08-2024 | E8: LICITAÇÃO | F8: EM ANDAMENTO | G8: ALUCOM | H8: UNIVERSIDADE FEDERAL DO CEARÁ | I8: O objeto do presente instrumento é a contratação de solução de tecnologia da informação e comunicação de de serviço de Outsourcing de impressão, por Sistema de Registro de Preços (SRP), com fornecimento de suprimentos, peças de reposição e manutenção, para equipamentos alocados nos diversos setores, nos Campi de Fortaleza e do interior do estado do Ceará, que serão prestados nas condições estabelecidas no Termo de Referência, anexo do Edital.
A9: 8 | B9: IFCE CAMOCIM | C9: 04/2024 | E9: LICITAÇÃO | F9: EM ANDAMENTO | G9: ALUCOM | H9: INSTITUTO FEDERAL DE EDUCAÇÃO E TECNOLOGIA - IFCE CAMOCIM | I9: O objeto do presente instrumento é a contratação de solução de tecnologia da informação e comunicação de serviço de outsourcing de impressão, com fornecimento de suprimentos, peças de reposição e manutenção, para equipamentos alocados no Instituto Federal de Educação, Ciência e Tecnologia do Ceará - campus Camocim, que serão prestados nas condições estabelecidas no Termo de Referência, anexo do Edital.
A10: 9 | B10: IFCE CAUCAIA | C10: 03-2024 | E10: LICITAÇÃO | F10: EM ANDAMENTO | G10: ALUCOM | H10: INSTITUTO FEDERAL DE EDUCAÇÃO E TECNOLOGIA - IFCE CAUCAIA | I10: O objeto do presente instrumento é a contratação de solução de tecnologia da informação e comunicação de serviço de Outsourcing de impressão, por Sistema de Registro de Preços (SRP), com fornecimento de suprimentos, peças de reposição e manutenção, para equipamentos alocados no IFCE Campus Caucaia, que serão prestados nas condições estabelecidas no Termo de Referência, anexo do Edital.
A11: 10 | B11: IFCE ITAPIPOCA | C11: 04/2024 | E11: LICITAÇÃO | F11: EM ANDAMENTO | G11: ALUCOM | H11: INSTITUTO FEDERAL DE EDUCAÇÃO E TECNOLOGIA - IFCE ITAPIPOCA | I11: O objeto do presente instrumento é a contratação de solução de tecnologia da informação e comunicação de serviço de Outsourcing de impressão, por Sistema de Registro de Preços (SRP), com fornecimento de suprimentos, peças de reposição e manutenção, para equipamentos alocados no Instituto Federal de Educação, Ciência e Tecnologia do Ceará - IFCE/Campus Itapipoca, que serão prestados nas condições estabelecidas no Termo de Referência anexo ao Edital do PregãoEletrônico Nº 52/2023.
A12: 11 | B12: IFCE PARACURU | C12: 02/2024 | E12: LICITAÇÃO | F12: EM ANDAMENTO | G12: ALUCOM | H12: INSTITUTO FEDERAL DE EDUCAÇÃO E TECNOLOGIA - IFCE PARACURU | I12: O objeto do presente instrumento é a contratação de solução de tecnologia da informação e comunicação de serviço de Outsourcing de impressão, por Sistema de Registro de Preços (SRP), com fornecimento de suprimentos, peças de reposição e manutenção, para equipamentos alocados nos diversos setores, no campus Paracuru
A13: 12 | B13: IFCE JUAZEIRO DO NORTE | C13: 05/2024 | E13: LICITAÇÃO | F13: EM ANDAMENTO | G13: ALUCOM | H13: INSTITUTO FEDERAL DE EDUCAÇÃO E TECNOLOGIA - IFCE JUAZEIRO DO NORTE | I13: O objeto do presente instrumento é a contratação de solução de tecnologia da informação e comunicação de serviço de Outsourcing de impressão, por Sistema de Registro de Preços (SRP), com fornecimento de suprimentos, peças de reposição e manutenção, para equipamentos alocados no Instituto Federal de Educação, Ciência e Tecnologia do Ceará (IFCE) - campus Juazeiro do Norte, que serão prestados nas condições estabelecidas no Termo de Referência anexo ao Edital do Pregão Eletrônico nº 52/2023.
A14: 13 | B14: MINISTÉRIO DA AGRICULTURA E PECUÁRIA/SUPERINTENDÊNCIA FEDERAL DE AGRICULTURA E PECUÁRIA NO PARANÁ (SFA-PR/MAPA) | C14: 10/2024 | E14: LICITAÇÃO | F14: EM ANDAMENTO | G14: ALUCOM | H14: MINISTÉRIO DA AGRICULTURA E PECUÁRIA/SUPERINTENDÊNCIA FEDERAL DE AGRICULTURA E PECUÁRIA NO PARANÁ (SFA-PR/MAPA) | I14: O objeto do presente instrumento é a Contratação de solução de tecnologia da informação e comunicação de outsourcing de impressão e digitalizaçãona modalidade franquia de página mais excedente, com fornecimento de equipamentos, soware de gerenciamento de impressão efe vamente realizadas,manutenção preven va e corre va dos equipamentos com subs tuição de peças, componentes e materiais u lizados na manutenção e fornecimento de insumosoriginais, exceto papel, para atender as necessidades de impressão e digitalização da Superintendência Federal de Agricultura e Pecuária no Paraná - SFA-PR, nascondições estabelecidas no Termo de Referência.
A15: 14 | B15: CAPITANIA DOS PORTOS DE SERGIPE | C15: 82320/202461/00 | E15: LICITAÇÃO | F15: EM ANDAMENTO | G15: ALUCOM | H15: CAPITANIA DOS PORTOS DE SERGIPE | I15: O objeto do presente instrumento é a contratação de empresa especializada na prestaçãode serviço de Outsourcing de impressão, por Sistema de Registro de Preços (SRP), comfornecimento de suprimentos, peças de reposição e manutenção, para equipamentos queserão alocados na Capitania dos Portos de Sergipe
... A38: 37 | B38: SEGER | C38: 026-2022 - SEGER | E38: LICITAÇÃO | F38: EM ANDAMENTO | G38: ALUCOM | H38: SECRETARIA MUNICIPAL DA GESTÃO REGIONAL - SEGER | I38: O presente contrato tem como fundamento a adesão ao Edital do Pregão Eletrônico tombado sob o n° 2021.08.02.01 em conformidade com a Lei Federal N° 8.666/93 - Lei das Licitações Públicas, c/c os termos da Lei Federal n° 10.520, de 17/07/2002., os preceitos do direito público, com suas alterações e, ainda, outras leis especiais necessárias ao cumprimento de seu objeto.
A39: 38 | B39: CEGOR | C39: Nº 26/2022 - SEGER – SUB-ROGADO CEGOR | D39: 37 | E39: SUB-ROGAÇÃO | F39: EM ANDAMENTO | G39: ALUCOM | H39: COORDENADORIA ESPECIAL DE APOIO À GOVERNANÇA DAS REGIONAIS – CEGOR | I39: O presente contrato tem como fundamento a adesão ao Edital do Pregão Eletrônico tombado sob o n° 2021.08.02.01 em conformidade com a Lei Federal N° 8.666/93 - Lei das Licitações Públicas, c/c os termos da Lei Federal n° 10.520, de 17/07/2002., os preceitos do direito público, com suas alterações e, ainda, outras leis especiais necessárias ao cumprimento de seu objeto.
A40: 39 | B40: DETRAN MA | C40: 06/2024-DETRAN/MA | E40: LICITAÇÃO | F40: EM ANDAMENTO | G40: ALUCOM | H40: DETRAN | I40: Locação de equipamentos de informática (desktops, notebooks, no breaks, entre outros) com instalação, manutenção, suporte e gestão do ambiente de TI, e execução continuada de atividades relativas a incidentes e solicitações de serviços, incluindo suporte, assistência técnica e disponibilização de central de serviços.
A41: 40 | B41: IPAM | C41: 0014/2022 | E41: LICITAÇÃO | F41: EM ANDAMENTO | G41: ALUCOM | H41: IPAM | I41: Contratação de empresa especializada na prestação de serviços, executados de forma contínua, de locação e manutenção preventiva e corretiva de equipamentos de informática.
A42: 41 | B42: PCDF | C42: 11/2025 | E42: LICITAÇÃO | F42: EM ANDAMENTO | G42: ALUCOM | H42: POLICIA CIVIL DO DISTRITO FEDERAL | I42: O objeto do presente instrumento é a contratação de solução de tecnologia da informação e comunicação por meio da prestação continuada de serviços de impressão, cópia e digitalização para a PCDF, na modalidade Outsourcing de Impressão, pelo prazo de 60 meses, nas condições estabelecidas no Termo de Referência.
A43: 42 | B43: HEMOCENTRO PB | C43: 0096-2024 | E43: LICITAÇÃO | F43: EM ANDAMENTO | G43: ALUCOM | H43: SECRETARIA DE ESTADO DA SAÚDE - HEMOCENTRO | I43: Contratação de EMPRESA ESPECIALIZADA EM PRESTAÇÃODE SERVIÇO DE OUTSOURCING DE IMPRESSÃO, conforme especificações e quantitativos estabelecidos no Edital do Pregão identificado no preâmbulo e na proposta vencedora.
A44: 43 | B44: ALEMA | C44: 49/2023 | E44: LICITAÇÃO | F44: EM ANDAMENTO | G44: ALUCOM | H44: ASSEMBLEIA LEGISLATIVA DO ESTADO DO MARANHÃO | I44: locação de equipamentos de informática (desktops, notebooks, no breaks, dentre outros) com instalação, manutenção, suporte e gestão do ambiente de TI, e execução continuada de atividades referentes à incidentes e solicitações de serviços, com suporte, assistência técnica e disponibilização de central de serviços, visando futuras contratações pela Assembleia Legislativa do Estado do Maranhão
A45: 44 | B45: SEAP-PB | C45: 0025/2024 | E45: LICITAÇÃO | F45: EM ANDAMENTO | G45: ALUCOM | H45: SECRETARIA DE ESTADO DA ADMINISTRAÇÃO PENITENCIÁRIA – SEAP-PB | I45: Contratação de serviços de outsurcing de impressão, em conformidade com as especificações, exigências e quantitativos, estabelecidos no Termo de Referência.
A46: 45 | B46: PCPB | C46: 0005/2024/PCPB | E46: LICITAÇÃO | F46: EM ANDAMENTO | G46: ALUCOM | H46: POLICIA CIVIL DA PARAIBA | I46: O objeto do presente instrumento é a contratação de serviços de outsourcing de impressão e digitalização corporativa, que serão prestados nas condições estabelecidas no Termo de Referência, anexo do Edital, visando atender às necessidades da Polícia Civil Do Estado Da Paraíba
A47: 46 | B47: SETUR | C47: nº 2024.000006.37101.01 | E47: LICITAÇÃO | F47: EM ANDAMENTO | G47: ALUCOM | H47: SETUR | I47: O presente Contrato tem por objeto a prestação de serviços de serviço de outsourcing de impressão, compreendendo disponibilização de equipamento(s) reprográfic (s)multifuncional(is) monocromático(s), assistência técnica, fornecimento de peças e demais insumos consumíveis
A48: 47 | B48: CITINOVA | C48: 005/2022 | E48: LICITAÇÃO | F48: EM ANDAMENTO | G48: ALUCOM | H48: FUNDACAO CITINOVA | I48: locações de equipamentos de informática, com suporte, assistência técnica e manutenção preventiva e corretiva in-loco, bem como atuação nos processos de gerenciamento de serviços, com base em melhores práticas definidas pela ITIL – Information Technology Infrastructure Library®, cujos serviços serão avaliados através de acordos de nível de serviço, para atender às necessidades administrativas da Fundação de Ciência, Tecnologia e Inovação – CITINOVA
A49: 48 | B49: RESENDE / SMA | C49: 17/2024 | E49: LICITAÇÃO | F49: EM ANDAMENTO | G49: ALUCOM | H49: RESENDE - SECRETARIA MUNICIPAL DE ADMINISTRAÇÃO / SMA | I49: CONTRATAÇÃO DE EMPRESA ESPECIALIZADA NO FORNECIMENTO DE SOLUÇÃO CONTINUADA SERVIÇOS OUTSOURCING (IMPRESSÃO E CÓPIA), INTEGRADA A SISTEMAS CORPORATIVOS E À REDE DA PREFEITURA MUNICIPAL DE RESENDE, COMPREENDENDO A CESSÃO DE DIREITO DE USO DE EQUIPAMENTOS NOVOS E DE PRIMEIRO USO (FRANQUIA MENSAL DE PÁGINAS MAIS EXCEDENTE), INCLUINDO A PRESTAÇÃO DE SERVIÇOS DE MANUTENÇÃO PREVENTIVA E CORRETIVA, FORNECIMENTO DE PEÇAS E CONSUMÍVEIS NECESSÁRIOS (EXCETO PAPEL), ASSIM COMO SISTEMA DE GESTÃO, CONTROLE E OPERACIONALIZAÇÃO DA SOLUÇÃO, VISANDO ATENDER ÀS NECESSIDADES DA PREFEITURA MUNICIPAL DE RESENDE, POR MEIO DA SECRETARIA MUNICIPAL DE ADMINISTRAÇÃO- SMA/ SUMTI, PELO PERÍODO DE 12 MESES
A50: 49 | B50: SECRETARIA MUNICIPAL DE SEGURANÇA COM CIDADANIA−SEMUSC - 007-2022 | C50: 007-2022 | E50: LICITAÇÃO | F50: EM ANDAMENTO | G50: ALUCOM | H50: SECRETARIA MUNICIPAL DE SEGURANÇA COM CIDADANIA−SEMUSC | I50: O objeto do contrato nº 007/2022-SEMUSC consiste na contratação de uma empresa especializada para a prestação de serviços de locação e manutenção de equipamentos de informática
A51: 50 | B51: CAMARA DE HORTOLANDIA | C51: 29-2023 | E51: LICITAÇÃO | F51: EM ANDAMENTO | G51: ALUCOM | H51: CAMARA MUNICIPAL DE HORTOLÂNDIA | I51: O objeto do presente instrumento é a contratação de serviço contínuo especializado de Impressão, cópias e digitalização corporativa, por meio de sistema Outsourcing,na modalidade de franquia de páginas mais excedente, incluindo fornecimento de equipamentos, manutenção preventiva e corretiva dos equipamentos, com fornecimento de peças e componentes originais, suprimentos, componentes, papel, softwares de gerenciamento e controle (bilhetagem) de cópias e impressões, suporte técnico remoto durante ohorário de expediente da Contratante e com visita técnica diária de segunda a sexta-feira,conforme especificação no Termo de Referência - Retificado, constante do Anexo Únicodeste Contrato.
... A86: 86 | B86: HOSPITAL MUNICIPAL DR. AUGEU BRAGA HERBSTER | C86: 09.25.03.03.001 | E86: LICITAÇÃO | F86: EM ANDAMENTO | G86: ALUCOM | H86: MARANGUAPE - PREFEITURA MUNICIPAL DE MARANGUAPE | I86: Locações de equipamentos de informática, com suporte, assistência técnica e manutenção preventiva e corretiva in-loco de interesse do Hospital Municipal Dr. Augeu Braga Herbster
A87: 87 | B87: PREFEITURA MUNICIPAL DE MARANGUAPE - AGRICULTURA, PESCA E RECURSOS HÍDRICOS | C87: 11.25.03.03.001 | E87: LICITAÇÃO | F87: EM ANDAMENTO | G87: ALUCOM | H87: MARANGUAPE - PREFEITURA MUNICIPAL DE MARANGUAPE
A88: 88 | B88: PREFEITURA MUNICIPAL DE MARANGUAPE - EDUCAÇÃO | C88: 04.25.03.03.001 | E88: LICITAÇÃO | F88: EM ANDAMENTO | G88: ALUCOM | H88: MARANGUAPE - PREFEITURA MUNICIPAL DE MARANGUAPE | I88: Locações de equipamentos de informática (20 notebooks e 70 micro desktops), incluindo suporte, assistência técnica e manutenção preventiva e corretiva in-loco para a Secretaria de Educação do Município de Maranguape-CE
A89: 89 | B89: CÂMARA MUNICIPAL DE CAUCAIA | C89: 042/2022 | E89: LICITAÇÃO | F89: EM ANDAMENTO | G89: ALUCOM | H89: CÂMARA MUNICIPAL DE CAUCAIA | I89: CONTRATAÇÕES DE SERVIÇOS DE LOCAÇÕES DE EQUIPAMENTOS DE INFORMÁTICA, COM SUPORTE, ASSISTÊNCIA TÉCNICA E MANUTENÇÃO PREVENTIVA E CORRETIVA IN-LOCO, JUNTO A CÂMARA MUNICIPAL DE CAUCAIA-CE, tudo conforme especificações contidas no Projeto Básico/Termo de Referência, constante do Anexo I do Edital.
A90: 90 | B90: PREFEITURA MUNICIPAL DE ARACATI - DESENV ECON, TRAB E RENDA | C90: 2022041303 | E90: LICITAÇÃO | F90: EM ANDAMENTO | G90: ALUCOM | H90: PREFEITURA MUNICIPAL DE ARACATI - DESENV ECON, TRAB E RENDA | I90: CONTRATAÇÃO DE SERVIÇOS DE LOCAÇÃO DE EQUIPAMENTOS DE INFORMÁTICA, COM SUPORTE, ASSISTÊNCIA TÉCNICA E MANUTENÇÃO PREVENTIVA E CORRETIVA IN LOCO, BEM COMO ATUAÇÃO NOS PROCESSOS DE GERENCIAMENTO DE SERVIÇOS.
A91: 91 | B91: PREFEITURA MUNICIPAL DE CAUCAIA - TURISMO E CULTURA | C91: 2021.08.02.01-11 | E91: LICITAÇÃO | F91: EM ANDAMENTO | G91: ALUCOM | H91: PREFEITURA MUNICIPAL DE CAUCAIA - TURISMO E CULTURA | I91: CONTRATAÇÃO DE SERVIÇOS DE LOCAÇÕES DE EQUIPAMENTOS DE INFORMÁTICA, COM SUPORTE, ASSISTÊNCIA TÉCNICA E MANUTENÇÃO PREVENTIVA E CORRETIVA IN-LOCO, BEM COMO ATUAÇÃO NOS PROCESSOS DE GERENCIAMENTO DE SERVIÇOS, COM BASE EM MELHORES PRÁTICAS DEFINIDAS PELA ITIL-INFORMATION TECHNOLOGY INFRASTRUCTURE LIBRARY, CUJOS SERVIÇOS SERÃO AVALIADOS ATRAVÉS DE ACORDOS DE NÍVEL DE SERVIÇO, PARA ATENDER AS NECESSIDADES DA SECRETARIA MUNICIPAL DE TURISMO E CULTURA DO MUNICÍPIO DE CAUCAIA-CE
A92: 92 | B92: PREFEITURA MUNICIPAL DE CAUCAIA - ADMINISTRAÇÃO E RECURSOS HUMANOS | C92: 2021.08.02.01-01 | E92: LICITAÇÃO | F92: EM ANDAMENTO | G92: ALUCOM | H92: PREFEITURA MUNICIPAL DE CAUCAIA - ADMINISTRAÇÃO E RECURSOS HUMANOS | I92: CONTRATAÇÃO DE SERVIÇOS DE LOCAÇÕES DE EQUIPAMENTOS DE INFORMÁTICA, COM SUPORTE, ASSISTÊNCIA TÉCNICA E MANUTENÇÃO PREVENTIVA E CORRETIVA IN-LOCO, BEM COMO ATUAÇÃO NOS PROCESSOS DE GERENCIAMENTO DE SERVIÇOS, COM BASE EM MELHORES PRÁTICAS DEFINIDAS PELA ITIL-INFORMATION TECHNOLOGY INFRASTRUCTURE LIBRARY, CUJOS SERVIÇOS SERÃO AVALIADOS ATRAVÉS DE ACORDOS DE NÍVEL DE SERVIÇO, PARA ATENDER AS NECESSIDADES DA SECRETARIA MUNICIPAL DE TURISMO E CULTURA DO MUNICÍPIO DE CAUCAIA-CE
A93: 93 | B93: PREFEITURA MUNICIPAL DE ARACATI - EDUCAÇÃO | C93: 20220413019 | E93: LICITAÇÃO | F93: EM ANDAMENTO | G93: ALUCOM | H93: PREFEITURA MUNICIPAL DE ARACATI - EDUCAÇÃO | I93: CONTRATAÇÃO DE SERVIÇOS DE LOCAÇÃO DE EQUIPAMENTOS DE INFORMÁTICA, COM SUPORTE, ASSISTÊNCIA TÉCNICA E MANUTENÇÃO PREVENTIVA E CORRETIVA IN LOCO, BEM COMO ATUAÇÃO NOS PROCESSOS DE GERENCIAMENTO DE SERVIÇOS.
A94: 94 | B94: PREFEITURA MUNICIPAL DE CAUCAIA - AUTARQUIA MUNICIPAL DE TRÂNSITO | C94: 2021.08.02.01-19 | E94: LICITAÇÃO | F94: EM ANDAMENTO | G94: ALUCOM | H94: PREFEITURA MUNICIPAL DE CAUCAIA - AUTARQUIA MUNICIPAL DE TRÂNSITO | I94: CONTRATAÇÃO DE SERVIÇOS DE LOCAÇÕES DE EQUIPAMENTOS DE INFORMÁTICA, COM SUPORTE, ASSISTÊNCIA TÉCNICA E MANUTENÇÃO PREVENTIVA E CORRETIVA IN-LOCO, BEM COMO ATUAÇÃO NOS PROCESSOS DE GERENCIAMENTO DE SERVIÇOS, COM BASE EM MELHORES PRÁTICAS DEFINIDAS PELA ITIL-INFORMATION TECHNOLOGY INFRASTRUCTURE LIBRARY, CUJOS SERVIÇOS SERÃO AVALIADOS ATRAVÉS DE ACORDOS DE NÍVEL DE SERVIÇO, PARA ATENDER AS NECESSIDADES DA SECRETARIA MUNICIPAL DE TURISMO E CULTURA DO MUNICÍPIO DE CAUCAIA-CE
A95: 95 | B95: PREFEITURA MUNICIPAL DE CANINDE - SECRETARIA DE ASSISTÊNCIA SOCIAL | C95: 20230929012 | E95: LICITAÇÃO | F95: EM ANDAMENTO | G95: ALUCOM | H95: PREFEITURA MUNICIPAL DE CANINDE - SECRETARIA DE ASSISTÊNCIA SOCIAL
A96: 96 | B96: PREFEITURA MUNICIPAL DE ARACATI - ESPORTE E LAZER | C96: 20220413005 | E96: LICITAÇÃO | F96: EM ANDAMENTO | G96: ALUCOM | H96: PREFEITURA MUNICIPAL DE ARACATI - ESPORTE E LAZER | I96: CONTRATAÇÃO DE SERVIÇOS DE LOCAÇÃO DE EQUIPAMENTOS DE INFORMÁTICA, COM SUPORTE, ASSISTÊNCIA TÉCNICA E MANUTENÇÃO PREVENTIVA E CORRETIVA IN LOCO, BEM COMO ATUAÇÃO NOS PROCESSOS DE GERENCIAMENTO DE SERVIÇOS.
A97: 97 | B97: PREFEITURA MUNICIPAL DE ARACATI - FINANÇAS | C97: 20220413004 | E97: LICITAÇÃO | F97: EM ANDAMENTO | G97: ALUCOM | H97: PREFEITURA MUNICIPAL DE ARACATI - FINANÇAS | I97: CONTRATAÇÃO DE SERVIÇOS DE LOCAÇÃO DE EQUIPAMENTOS DE INFORMÁTICA, COM SUPORTE, ASSISTÊNCIA TÉCNICA E MANUTENÇÃO PREVENTIVA E CORRETIVA IN LOCO, BEM COMO ATUAÇÃO NOS PROCESSOS DE GERENCIAMENTO DE SERVIÇOS.
A98: 98 | B98: PREFEITURA MUNICIPAL DE ARACATI - SEGURIDADE SOCIAL | C98: 20220413009 | E98: LICITAÇÃO | F98: EM ANDAMENTO | G98: ALUCOM | H98: PREFEITURA MUNICIPAL DE ARACATI - SEGURIDADE SOCIAL | I98: CONTRATAÇÃO DE SERVIÇOS DE LOCAÇÃO DE EQUIPAMENTOS DE INFORMÁTICA, COM SUPORTE, ASSISTÊNCIA TÉCNICA E MANUTENÇÃO PREVENTIVA E CORRETIVA IN LOCO, BEM COMO ATUAÇÃO NOS PROCESSOS DE GERENCIAMENTO DE SERVIÇOS.
...

Sheet EVENTO
A1: ID | B1: TIPO | C1: CONTRATO
A7: 6 | B7: CADASTRO | C7: ALECE
A8: 7 | B8: ADITIVO DE QUANTIDADE | C8: ALECE
A9: 8 | B9: CADASTRO | C9: 10a REGIAO MILITAR
A10: 9 | B10: ADITIVO DE REAJUSTE E PRAZO | C10: 10a REGIAO MILITAR
A11: 10 | B11: CADASTRO | C11: CMFOR
A12: 11 | B12: ADITIVO DE REAJUSTE E PRAZO | C12: CMFOR
A13: 12 | B13: ADITIVO DE REAJUSTE E PRAZO | C13: CMFOR
A14: 13 | B14: CADASTRO | C14: ESCOLA DE APRENDIZEM DE MARINHEIROS DO CEARÁ
A15: 14 | B15: ADITIVO DE REAJUSTE E PRAZO | C15: ESCOLA DE APRENDIZEM DE MARINHEIROS DO CEARÁ
A16: 15 | B16: CADASTRO | C16: UFC
A17: 16 | B17: ADITIVO DE PRAZO | C17: UFC
A18: 17 | B18: APOSTILAMENTO | C18: UFC
... A731: 732 | B731: ADITIVO DE PRAZO | C731: MUNICIPIO DE GRANJA - CÂMARA MUNICIPAL DE GRANJA
A732: 733
A733: 734
A734: 735
A735: 736
A736: 737
A737: 738
A738: 739
A739: 740
A740: 741
A741: 742
A742: 743
A743: 744
... A998: 999

Sheet INFORMAÇÕES
A1: EVENTO | B1: TIPO_EVENTO | C1: CONTRATO | D1: DATA_INICIAL | E1: DURAÇÃO (MESES) | F1: DURAÇÃO_MAXIMA (MESES) | G1: DATA_FINAL | H1: DATA_FINAL_MAXIMA | I1: VALOR TOTAL
B2: =IFERROR(VLOOKUP($A2,EVENTO!$A$2:$C$4999,2,FALSE),"") | C2: =IFERROR(VLOOKUP($A2,EVENTO!$A$2:$C$4999,3,FALSE),"")
B3: =IFERROR(VLOOKUP($A3,EVENTO!$A$2:$C$4999,2,FALSE),"") | C3: =IFERROR(VLOOKUP($A3,EVENTO!$A$2:$C$4999,3,FALSE),"")
B4: =IFERROR(VLOOKUP($A4,EVENTO!$A$2:$C$4999,2,FALSE),"") | C4: =IFERROR(VLOOKUP($A4,EVENTO!$A$2:$C$4999,3,FALSE),"")
A5: 6 | B5: =IFERROR(VLOOKUP($A5,EVENTO!$A$2:$C$4999,2,FALSE),"") -> CADASTRO | C5: =IFERROR(VLOOKUP($A5,EVENTO!$A$2:$C$4999,3,FALSE),"") -> ALECE | D5: 45918 | E5: 12 | F5: 120 | G5: 46251 | H5: 49538 | I5: 1557184.6
A6: 7 | B6: =IFERROR(VLOOKUP($A6,EVENTO!$A$2:$C$4999,2,FALSE),"") -> ADITIVO DE QUANTIDADE | C6: =IFERROR(VLOOKUP($A6,EVENTO!$A$2:$C$4999,3,FALSE),"") -> ALECE | D6: 45992 | E6: 9 | F6: 120 | G6: 46286 | H6: 49538 | I6: 312999.6
A7: 8 | B7: =IFERROR(VLOOKUP($A7,EVENTO!$A$2:$C$4999,2,FALSE),"") -> CADASTRO | C7: =IFERROR(VLOOKUP($A7,EVENTO!$A$2:$C$4999,3,FALSE),"") -> 10a REGIAO MILITAR | D7: 45336 | E7: 12 | F7: 48 | G7: 45702 | H7: 46797 | I7: 34044
A8: 9 | B8: =IFERROR(VLOOKUP($A8,EVENTO!$A$2:$C$4999,2,FALSE),"") -> ADITIVO DE REAJUSTE E PRAZO | C8: =IFERROR(VLOOKUP($A8,EVENTO!$A$2:$C$4999,3,FALSE),"") -> 10a REGIAO MILITAR | D8: 45703 | E8: 12 | F8: 36 | G8: 46067 | H8: 46797 | I8: 35311.2
A9: 10 | B9: =IFERROR(VLOOKUP($A9,EVENTO!$A$2:$C$4999,2,FALSE),"") -> CADASTRO | C9: =IFERROR(VLOOKUP($A9,EVENTO!$A$2:$C$4999,3,FALSE),"") -> CMFOR | D9: 45197 | E9: 12 | F9: 120 | G9: 45563 | H9: 48850 | I9: 35341.2
A10: 11 | B10: =IFERROR(VLOOKUP($A10,EVENTO!$A$2:$C$4999,2,FALSE),"") -> ADITIVO DE REAJUSTE E PRAZO | C10: =IFERROR(VLOOKUP($A10,EVENTO!$A$2:$C$4999,3,FALSE),"") -> CMFOR | D10: 45564 | E10: 12 | F10: 120 | G10: 45928 | H10: 48850 | I10: 36816.96
A11: 12 | B11: =IFERROR(VLOOKUP($A11,EVENTO!$A$2:$C$4999,2,FALSE),"") -> ADITIVO DE REAJUSTE E PRAZO | C11: =IFERROR(VLOOKUP($A11,EVENTO!$A$2:$C$4999,3,FALSE),"") -> CMFOR | D11: 45929 | E11: 12 | F11: 120 | G11: 46293 | H11: 48850 | I11: 39051.72
A12: 13 | B12: =IFERROR(VLOOKUP($A12,EVENTO!$A$2:$C$4999,2,FALSE),"") -> CADASTRO | C12: =IFERROR(VLOOKUP($A12,EVENTO!$A$2:$C$4999,3,FALSE),"") -> ESCOLA DE APRENDIZEM DE MARINHEIROS DO CEARÁ | D12: 45331 | E12: 12 | F12: 60 | G12: 45330 | H12: 47157 | I12: 6000
A13: 14 | B13: =IFERROR(VLOOKUP($A13,EVENTO!$A$2:$C$4999,2,FALSE),"") -> ADITIVO DE REAJUSTE E PRAZO | C13: =IFERROR(VLOOKUP($A13,EVENTO!$A$2:$C$4999,3,FALSE),"") -> ESCOLA DE APRENDIZEM DE MARINHEIROS DO CEARÁ | D13: 45710 | E13: 12 | F13: 60 | G13: 46075 | H13: 47157 | I13: 6384
A14: 15 | B14: =IFERROR(VLOOKUP($A14,EVENTO!$A$2:$C$4999,2,FALSE),"") -> CADASTRO | C14: =IFERROR(VLOOKUP($A14,EVENTO!$A$2:$C$4999,3,FALSE),"") -> UFC | D14: 45314 | E14: 12 | F14: 60 | G14: 45679 | H14: 47140 | I14: 182773.68
A15: 16 | B15: =IFERROR(VLOOKUP($A15,EVENTO!$A$2:$C$4999,2,FALSE),"") -> ADITIVO DE PRAZO | C15: =IFERROR(VLOOKUP($A15,EVENTO!$A$2:$C$4999,3,FALSE),"") -> UFC | D15: 45681 | E15: 12 | F15: 60 | G15: 46046 | H15: 47140 | I15: 182773.68
A16: 17 | B16: =IFERROR(VLOOKUP($A16,EVENTO!$A$2:$C$4999,2,FALSE),"") -> APOSTILAMENTO | C16: =IFERROR(VLOOKUP($A16,EVENTO!$A$2:$C$4999,3,FALSE),"") -> UFC | D16: 45658 | E16: 12 | F16: 60 | G16: 46022 | H16: 47140 | I16: 191604.02
... A29: 30 | B29: =IFERROR(VLOOKUP($A29,EVENTO!$A$2:$C$4999,2,FALSE),"") -> CADASTRO | C29: =IFERROR(VLOOKUP($A29,EVENTO!$A$2:$C$4999,3,FALSE),"") -> CAPITANIA DOS PORTOS DE SERGIPE | D29: 45516 | E29: 12 | F29: 60 | G29: 45882 | H29: 47343 | I29: 21480
A30: 31 | B30: =IFERROR(VLOOKUP($A30,EVENTO!$A$2:$C$4999,2,FALSE),"") -> ADITIVO DE REAJUSTE E PRAZO | C30: =IFERROR(VLOOKUP($A30,EVENTO!$A$2:$C$4999,3,FALSE),"") -> CAPITANIA DOS PORTOS DE SERGIPE | D30: 45883 | E30: 12 | F30: 60 | G30: 46247 | H30: 47343 | I30: 22667.84 | AA30: /
A31: 32 | B31: =IFERROR(VLOOKUP($A31,EVENTO!$A$2:$C$4999,2,FALSE),"") -> CADASTRO | C31: =IFERROR(VLOOKUP($A31,EVENTO!$A$2:$C$4999,3,FALSE),"") -> IFRN CAMPUS CEARÁ-MIRIM | D31: 45429 | E31: 12 | F31: 60 | G31: 45794 | H31: 47255 | I31: 15798
A32: 33 | B32: =IFERROR(VLOOKUP($A32,EVENTO!$A$2:$C$4999,2,FALSE),"") -> ADITIVO DE REAJUSTE E PRAZO | C32: =IFERROR(VLOOKUP($A32,EVENTO!$A$2:$C$4999,3,FALSE),"") -> IFRN CAMPUS CEARÁ-MIRIM | D32: 45794 | E32: 12 | F32: 60 | G32: 46159 | H32: 47255 | I32: 16705.2
A33: 34 | B33: =IFERROR(VLOOKUP($A33,EVENTO!$A$2:$C$4999,2,FALSE),"") -> CADASTRO | C33: =IFERROR(VLOOKUP($A33,EVENTO!$A$2:$C$4999,3,FALSE),"") -> IFRN CAMPUS NATAL | D33: 45597 | E33: 12 | F33: 60 | G33: 45961 | H33: 47422 | I33: 24900
A34: 35 | B34: =IFERROR(VLOOKUP($A34,EVENTO!$A$2:$C$4999,2,FALSE),"") -> ADITIVO DE REAJUSTE E PRAZO | C34: =IFERROR(VLOOKUP($A34,EVENTO!$A$2:$C$4999,3,FALSE),"") -> IFRN CAMPUS NATAL | D34: 46326 | E34: 12 | F34: 60 | G34: 46326 | H34: 47422 | I34: 26091.51
A35: 36 | B35: =IFERROR(VLOOKUP($A35,EVENTO!$A$2:$C$4999,2,FALSE),"") -> CADASTRO | C35: =IFERROR(VLOOKUP($A35,EVENTO!$A$2:$C$4999,3,FALSE),"") -> TRE RJ | D35: 45355 | E35: 24 | F35: 60 | G35: 46084 | H35: 47180 | I35: 1540816.5
A36: 37 | B36: =IFERROR(VLOOKUP($A36,EVENTO!$A$2:$C$4999,2,FALSE),"") -> CADASTRO | C36: =IFERROR(VLOOKUP($A36,EVENTO!$A$2:$C$4999,3,FALSE),"") -> DELEGACIA DA CAPITANIA DE SÃO FRANCISCO DO SUL | D36: 45677 | E36: 24 | F36: 60 | G36: 46406 | H36: 47502 | I36: 28430.4
A37: 38 | B37: =IFERROR(VLOOKUP($A37,EVENTO!$A$2:$C$4999,2,FALSE),"") -> CADASTRO | C37: =IFERROR(VLOOKUP($A37,EVENTO!$A$2:$C$4999,3,FALSE),"") -> DELEGACIA DA CAPITANIA DOS PORTOS EM ITAJAÍ | D37: 45696 | E37: 48 | F37: 60 | G37: 47156 | H37: 47521 | I37: 883987.2
A38: 39 | B38: =IFERROR(VLOOKUP($A38,EVENTO!$A$2:$C$4999,2,FALSE),"") -> CADASTRO | C38: =IFERROR(VLOOKUP($A38,EVENTO!$A$2:$C$4999,3,FALSE),"") -> SUPERINTENDÊNCIA FEDERAL DE AGRICULTURA E PECUARIA NO ESTADO DE SANTA CATARINA - SFA-SC | D38: 45536 | E38: 48 | F38: 60 | G38: 46996 | H38: 47361 | I38: 140517.12
A39: 40 | B39: =IFERROR(VLOOKUP($A39,EVENTO!$A$2:$C$4999,2,FALSE),"") -> CADASTRO | C39: =IFERROR(VLOOKUP($A39,EVENTO!$A$2:$C$4999,3,FALSE),"") -> UFSC | D39: 45429 | E39: 48 | F39: 60 | G39: 46890 | H39: 47255 | I39: 4774152
A40: 41 | B40: =IFERROR(VLOOKUP($A40,EVENTO!$A$2:$C$4999,2,FALSE),"") -> CADASTRO | C40: =IFERROR(VLOOKUP($A40,EVENTO!$A$2:$C$4999,3,FALSE),"") -> BASE ADMINISTRATIVA DO QUARTEL-GENERAL DO EXÉRCITO | D40: 45785 | E40: 12 | F40: 120 | G40: 46149 | H40: 49436 | I40: 40128
A41: 42 | B41: =IFERROR(VLOOKUP($A41,EVENTO!$A$2:$C$4999,2,FALSE),"") -> CADASTRO | C41: =IFERROR(VLOOKUP($A41,EVENTO!$A$2:$C$4999,3,FALSE),"") -> MCID | D41: 45785 | E41: 12 | F41: 120 | G41: 46149 | H41: 49436 | I41: 74412.71
A42: 43 | B42: =IFERROR(VLOOKUP($A42,EVENTO!$A$2:$C$4999,2,FALSE),"") -> CADASTRO | C42: =IFERROR(VLOOKUP($A42,EVENTO!$A$2:$C$4999,3,FALSE),"") -> COTER | D42: 45839 | E42: 60 | F42: 120 | G42: 47664 | H42: 49490 | I42: 616118.4
... A68: 69 | B68: =IFERROR(VLOOKUP($A68,EVENTO!$A$2:$C$4999,2,FALSE),"") -> CADASTRO | C68: =IFERROR(VLOOKUP($A68,EVENTO!$A$2:$C$4999,3,FALSE),"") -> DETRAN MA | D68: 45506 | E68: 12 | F68: 60 | G68: 45870 | H68: 47331 | I68: 1855597.2
A69: 70 | B69: =IFERROR(VLOOKUP($A69,EVENTO!$A$2:$C$4999,2,FALSE),"") -> CADASTRO | C69: =IFERROR(VLOOKUP($A69,EVENTO!$A$2:$C$4999,3,FALSE),"") -> IPAM | D69: 44746 | E69: 12 | F69: 48 | G69: 45111 | H69: 46207 | I69: R$ 95.061,60
A70: 74 | B70: =IFERROR(VLOOKUP($A70,EVENTO!$A$2:$C$4999,2,FALSE),"") -> CADASTRO | C70: =IFERROR(VLOOKUP($A70,EVENTO!$A$2:$C$4999,3,FALSE),"") -> PCDF | D70: 45723 | E70: 60 | F70: 120 | G70: 47548 | H70: 49374 | I70: 10433984
A71: 71 | B71: =IFERROR(VLOOKUP($A71,EVENTO!$A$2:$C$4999,2,FALSE),"") -> ADITIVO DE QUANTIDADE E PRAZO | C71: =IFERROR(VLOOKUP($A71,EVENTO!$A$2:$C$4999,3,FALSE),"") -> IPAM | D71: 45111 | E71: 12 | F71: 48 | G71: 45477 | H71: 46207 | I71: 101550.96
A72: 75 | B72: =IFERROR(VLOOKUP($A72,EVENTO!$A$2:$C$4999,2,FALSE),"") -> CADASTRO | C72: =IFERROR(VLOOKUP($A72,EVENTO!$A$2:$C$4999,3,FALSE),"") -> HEMOCENTRO PB | D72: 45383 | E72: 12 | F72: 60 | G72: 45746 | H72: 47207 | I72: 25872
A73: 76 | B73: =IFERROR(VLOOKUP($A73,EVENTO!$A$2:$C$4999,2,FALSE),"") -> CADASTRO | C73: =IFERROR(VLOOKUP($A73,EVENTO!$A$2:$C$4999,3,FALSE),"") -> ALEMA | D73: 45190 | E73: 12 | F73: 60 | G73: 45555 | H73: 47016 | I73: 4083177.6
A74: 72 | B74: =IFERROR(VLOOKUP($A74,EVENTO!$A$2:$C$4999,2,FALSE),"") -> ADITIVO DE PRAZO | C74: =IFERROR(VLOOKUP($A74,EVENTO!$A$2:$C$4999,3,FALSE),"") -> IPAM | D74: 45477 | E74: 12 | F74: 48 | G74: 45842 | H74: 46207 | I74: 101550.96
A75: 77 | B75: =IFERROR(VLOOKUP($A75,EVENTO!$A$2:$C$4999,2,FALSE),"") -> ADITIVO DE REAJUSTE E PRAZO | C75: =IFERROR(VLOOKUP($A75,EVENTO!$A$2:$C$4999,3,FALSE),"") -> HEMOCENTRO PB | D75: 45748 | E75: 12 | F75: 60 | G75: 46111 | H75: 47207 | I75: 29568
A76: 73 | B76: =IFERROR(VLOOKUP($A76,EVENTO!$A$2:$C$4999,2,FALSE),"") -> ADITIVO DE REAJUSTE E PRAZO | C76: =IFERROR(VLOOKUP($A76,EVENTO!$A$2:$C$4999,3,FALSE),"") -> IPAM | D76: 45842 | E76: 12 | F76: 48 | G76: 46207 | H76: 46207 | I76: 110.989.44
A77: 78 | B77: =IFERROR(VLOOKUP($A77,EVENTO!$A$2:$C$4999,2,FALSE),"") -> CADASTRO | C77: =IFERROR(VLOOKUP($A77,EVENTO!$A$2:$C$4999,3,FALSE),"") -> SEAP-PB | D77: 45376 | E77: 12 | F77: 60 | G77: 45740 | H77: 47201 | I77: 58028
...

Sheet ITENS
A1: EVENTO | B1: TIPO_EVENTO | C1: CONTRATO | D1: APELIDO | E1: DESCRICAO | F1: QUANTIDADE | G1: VALOR_UNITARIO
B2: =IFERROR(VLOOKUP($A2,EVENTO!$A$2:$C$4999,2,FALSE),"") | C2: =IFERROR(VLOOKUP($A2,EVENTO!$A$2:$C$4999,3,FALSE),"")
B3: =IFERROR(VLOOKUP($A3,EVENTO!$A$2:$C$4999,2,FALSE),"") | C3: =IFERROR(VLOOKUP($A3,EVENTO!$A$2:$C$4999,3,FALSE),"")
B4: =IFERROR(VLOOKUP($A4,EVENTO!$A$2:$C$4999,2,FALSE),"") | C4: =IFERROR(VLOOKUP($A4,EVENTO!$A$2:$C$4999,3,FALSE),"")
B5: =IFERROR(VLOOKUP($A5,EVENTO!$A$2:$C$4999,2,FALSE),"") | C5: =IFERROR(VLOOKUP($A5,EVENTO!$A$2:$C$4999,3,FALSE),"")
B6: =IFERROR(VLOOKUP($A6,EVENTO!$A$2:$C$4999,2,FALSE),"") | C6: =IFERROR(VLOOKUP($A6,EVENTO!$A$2:$C$4999,3,FALSE),"")
A7: 6 | B7: =IFERROR(VLOOKUP($A7,EVENTO!$A$2:$C$4999,2,FALSE),"") -> CADASTRO | C7: =IFERROR(VLOOKUP($A7,EVENTO!$A$2:$C$4999,3,FALSE),"") -> ALECE | D7: NOBREAK 700 VA | E7: FORCE LINE 0010400008 – UPS MAX SECURITY 700VA 115V | F7: 30 | G7: 42.25
A8: 6 | B8: =IFERROR(VLOOKUP($A8,EVENTO!$A$2:$C$4999,2,FALSE),"") -> CADASTRO | C8: =IFERROR(VLOOKUP($A8,EVENTO!$A$2:$C$4999,3,FALSE),"") -> ALECE | D8: NOBREAK 1,5 KVA | E8: FORCE LINE UPS OFFICE SECURITY PLUS 1500VA | F8: 20 | G8: 141.49
A9: 6 | B9: =IFERROR(VLOOKUP($A9,EVENTO!$A$2:$C$4999,2,FALSE),"") -> CADASTRO | C9: =IFERROR(VLOOKUP($A9,EVENTO!$A$2:$C$4999,3,FALSE),"") -> ALECE | D9: NOBREAK 3 KVA | E9: SMS POWER VISION NG 3000 VA | F9: 7 | G9: 390.98
A10: 6 | B10: =IFERROR(VLOOKUP($A10,EVENTO!$A$2:$C$4999,2,FALSE),"") -> CADASTRO | C10: =IFERROR(VLOOKUP($A10,EVENTO!$A$2:$C$4999,3,FALSE),"") -> ALECE | D10: NOBREAK 30 KVA | E10: NOBREAK 30 KVA TRIFÁSICO SCHNEIDER CLASSIC DSP | F10: 2 | G10: 3430.81
A11: 6 | B11: =IFERROR(VLOOKUP($A11,EVENTO!$A$2:$C$4999,2,FALSE),"") -> CADASTRO | C11: =IFERROR(VLOOKUP($A11,EVENTO!$A$2:$C$4999,3,FALSE),"") -> ALECE | D11: MONITOR | E11: DELL PRO 27 PLUS - P2724DEB | F11: 20 | G11: 73.78
A12: 6 | B12: =IFERROR(VLOOKUP($A12,EVENTO!$A$2:$C$4999,2,FALSE),"") -> CADASTRO | C12: =IFERROR(VLOOKUP($A12,EVENTO!$A$2:$C$4999,3,FALSE),"") -> ALECE | D12: NOTEBOOK TIPO 1 | E12: LENOVO E14 G2, I3-1115G, 256SSD, 8GB RAM | F12: 50 | G12: 249
A13: 6 | B13: =IFERROR(VLOOKUP($A13,EVENTO!$A$2:$C$4999,2,FALSE),"") -> CADASTRO | C13: =IFERROR(VLOOKUP($A13,EVENTO!$A$2:$C$4999,3,FALSE),"") -> ALECE | D13: NOTEBOOK TIPO 2 | E13: DELL LATITUDE 3450 + I7-1355U + 32GB RAM | F13: 10 | G13: 389
A14: 6 | B14: =IFERROR(VLOOKUP($A14,EVENTO!$A$2:$C$4999,2,FALSE),"") -> CADASTRO | C14: =IFERROR(VLOOKUP($A14,EVENTO!$A$2:$C$4999,3,FALSE),"") -> ALECE | D14: MICROCOMPUTADOR TIPO 1 | E14: LENOVO THINKCENTRE M70S, I5-10400, 8GB, SSD 512GB, WINDOWS 10 PRO, MOUSE E TECLADO USB LENOVO + MONITOR 21.5" LENOVO THINKVISION S22E-19 | F14: 200 | G14: 278.85
A15: 6 | B15: =IFERROR(VLOOKUP($A15,EVENTO!$A$2:$C$4999,2,FALSE),"") -> CADASTRO | C15: =IFERROR(VLOOKUP($A15,EVENTO!$A$2:$C$4999,3,FALSE),"") -> ALECE | D15: MICROCOMPUTADOR TIPO 2 | E15: LENOVO THINKCENTRE_M70S, I7-10700, 8GB, SSD 512GB, WINDOWS 10 PRO, MOUSE E TECLADO USB LENOVO + MONITOR 21.5" LENOVO THINKVISION T22I-20 | F15: 85 | G15: 330.2
A16: 6 | B16: =IFERROR(VLOOKUP($A16,EVENTO!$A$2:$C$4999,2,FALSE),"") -> CADASTRO | C16: =IFERROR(VLOOKUP($A16,EVENTO!$A$2:$C$4999,3,FALSE),"") -> ALECE | D16: MICROCOMPUTADOR TIPO 3 | E16: LENOVO WORDKSTATION P340 TWR, XEON W-1250, 32GB, SSD 256GB, GPU DIDICADA 2GB DDR5, MOUSE E TECLADO USB LENOVO + MONITOR 24,5 LENOVO LEGION Y25-25 | F16: 20 | G16: 720.85
A17: 7 | B17: =IFERROR(VLOOKUP($A17,EVENTO!$A$2:$C$4999,2,FALSE),"") -> ADITIVO DE QUANTIDADE | C17: =IFERROR(VLOOKUP($A17,EVENTO!$A$2:$C$4999,3,FALSE),"") -> ALECE | D17: NOBREAK 700 VA | E17: FORCE LINE 0010400008 – UPS MAX SECURITY 700VA 115V | F17: 30 | G17: 42.25
A18: 7 | B18: =IFERROR(VLOOKUP($A18,EVENTO!$A$2:$C$4999,2,FALSE),"") -> ADITIVO DE QUANTIDADE | C18: =IFERROR(VLOOKUP($A18,EVENTO!$A$2:$C$4999,3,FALSE),"") -> ALECE | D18: NOBREAK 1,5 KVA | E18: FORCE LINE UPS OFFICE SECURITY PLUS 1500VA | F18: 20 | G18: 141.49
... A21: 7 | B21: =IFERROR(VLOOKUP($A21,EVENTO!$A$2:$C$4999,2,FALSE),"") -> ADITIVO DE QUANTIDADE | C21: =IFERROR(VLOOKUP($A21,EVENTO!$A$2:$C$4999,3,FALSE),"") -> ALECE | D21: MONITOR | E21: DELL PRO 27 PLUS - P2724DEB | F21: 20 | G21: 73.78
A22: 7 | B22: =IFERROR(VLOOKUP($A22,EVENTO!$A$2:$C$4999,2,FALSE),"") -> ADITIVO DE QUANTIDADE | C22: =IFERROR(VLOOKUP($A22,EVENTO!$A$2:$C$4999,3,FALSE),"") -> ALECE | D22: NOTEBOOK TIPO 1 | E22: LENOVO E14 G2, I3-1115G, 256SSD, 8GB RAM | F22: =50+40 -> 90 | G22: 249
A23: 7 | B23: =IFERROR(VLOOKUP($A23,EVENTO!$A$2:$C$4999,2,FALSE),"") -> ADITIVO DE QUANTIDADE | C23: =IFERROR(VLOOKUP($A23,EVENTO!$A$2:$C$4999,3,FALSE),"") -> ALECE | D23: NOTEBOOK TIPO 2 | E23: DELL LATITUDE 3450 + I7-1355U + 32GB RAM | F23: 10 | G23: 389
A24: 7 | B24: =IFERROR(VLOOKUP($A24,EVENTO!$A$2:$C$4999,2,FALSE),"") -> ADITIVO DE QUANTIDADE | C24: =IFERROR(VLOOKUP($A24,EVENTO!$A$2:$C$4999,3,FALSE),"") -> ALECE | D24: MICROCOMPUTADOR TIPO 1 | E24: LENOVO THINKCENTRE M70S, I5-10400, 8GB, SSD 512GB, WINDOWS 10 PRO, MOUSE E TECLADO USB LENOVO + MONITOR 21.5" LENOVO THINKVISION S22E-19 | F24: =200+80 -> 280 | G24: 278.85
A25: 7 | B25: =IFERROR(VLOOKUP($A25,EVENTO!$A$2:$C$4999,2,FALSE),"") -> ADITIVO DE QUANTIDADE | C25: =IFERROR(VLOOKUP($A25,EVENTO!$A$2:$C$4999,3,FALSE),"") -> ALECE | D25: MICROCOMPUTADOR TIPO 2 | E25: LENOVO THINKCENTRE_M70S, I7-10700, 8GB, SSD 512GB, WINDOWS 10 PRO, MOUSE E TECLADO USB LENOVO + MONITOR 21.5" LENOVO THINKVISION T22I-20 | F25: 85 | G25: 330.2
A26: 7 | B26: =IFERROR(VLOOKUP($A26,EVENTO!$A$2:$C$4999,2,FALSE),"") -> ADITIVO DE QUANTIDADE | C26: =IFERROR(VLOOKUP($A26,EVENTO!$A$2:$C$4999,3,FALSE),"") -> ALECE | D26: MICROCOMPUTADOR TIPO 3 | E26: LENOVO WORDKSTATION P340 TWR, XEON W-1250, 32GB, SSD 256GB, GPU DIDICADA 2GB DDR5, MOUSE E TECLADO USB LENOVO + MONITOR 24,5 LENOVO LEGION Y25-25 | F26: 20 | G26: 720.85
A27: 8 | B27: =IFERROR(VLOOKUP($A27,EVENTO!$A$2:$C$4999,2,FALSE),"") -> CADASTRO | C27: =IFERROR(VLOOKUP($A27,EVENTO!$A$2:$C$4999,3,FALSE),"") -> 10a REGIAO MILITAR | D27: IMPRESSORA MONOCROMÁTICO – PÁGINAS A4 | E27: KYOCERA ECOSYSMA5500ifx + OCR | F27: 40
A28: 8 | B28: =IFERROR(VLOOKUP($A28,EVENTO!$A$2:$C$4999,2,FALSE),"") -> CADASTRO | C28: =IFERROR(VLOOKUP($A28,EVENTO!$A$2:$C$4999,3,FALSE),"") -> 10a REGIAO MILITAR | D28: IMPRESSORA POLICROMÁTICO – PÁGINAS – A4 | E28: KYOCERA ECOSYS MA3500cix + OCR | F28: 80
A29: 8 | B29: =IFERROR(VLOOKUP($A29,EVENTO!$A$2:$C$4999,2,FALSE),"") -> CADASTRO | C29: =IFERROR(VLOOKUP($A29,EVENTO!$A$2:$C$4999,3,FALSE),"") -> 10a REGIAO MILITAR | D29: IMPRESSORA MONOCROMÁTICO – PÁGINAS A3 | E29: KYOCERA TASKALFA 2554CI + DP-7160 + OCR | F29: 1
A30: 10 | B30: =IFERROR(VLOOKUP($A30,EVENTO!$A$2:$C$4999,2,FALSE),"") -> CADASTRO | C30: =IFERROR(VLOOKUP($A30,EVENTO!$A$2:$C$4999,3,FALSE),"") -> CMFOR | D30: IMPRESSÃO CORPORATIVA OU OUTSOURCING DE IMPRESSÃO, COM O FORNECIMENTO DE EQUIPAMENTOS | E30: KYOCERA M2640IDW + PF1100 | F30: 14
A31: 10 | B31: =IFERROR(VLOOKUP($A31,EVENTO!$A$2:$C$4999,2,FALSE),"") -> CADASTRO | C31: =IFERROR(VLOOKUP($A31,EVENTO!$A$2:$C$4999,3,FALSE),"") -> CMFOR | D31: IMPRESSÃO CORPORATIVA OU OUTSOURCING DE IMPRESSÃO, COM O FORNECIMENTO DE EQUIPAMENTOS | E31: KYOCERA TASKALFA 5004I | F31: 3
A32: 13 | B32: =IFERROR(VLOOKUP($A32,EVENTO!$A$2:$C$4999,2,FALSE),"") -> CADASTRO | C32: =IFERROR(VLOOKUP($A32,EVENTO!$A$2:$C$4999,3,FALSE),"") -> ESCOLA DE APRENDIZEM DE MARINHEIROS DO CEARÁ | D32: IMPRESSORA POLICROMÁTICO – PÁGINAS – A4 | E32: KYOCERA ECOSYS M6230cidn | F32: 2
A33: 15 | B33: =IFERROR(VLOOKUP($A33,EVENTO!$A$2:$C$4999,2,FALSE),"") -> CADASTRO | C33: =IFERROR(VLOOKUP($A33,EVENTO!$A$2:$C$4999,3,FALSE),"") -> UFC | D33: IMPRESSORA MONOCROMÁTICO – PÁGINAS A4 | E33: KYOCERA ECOSYSMA5500ifx + OCR | F33: 149
A34: 15 | B34: =IFERROR(VLOOKUP($A34,EVENTO!$A$2:$C$4999,2,FALSE),"") -> CADASTRO | C34: =IFERROR(VLOOKUP($A34,EVENTO!$A$2:$C$4999,3,FALSE),"") -> UFC | D34: IMPRESSORA POLICROMÁTICO – PÁGINAS – A4 | E34: KYOCERA ECOSYS MA3500cix + OCR | F34: 1
A35: 15 | B35: =IFERROR(VLOOKUP($A35,EVENTO!$A$2:$C$4999,2,FALSE),"") -> CADASTRO | C35: =IFERROR(VLOOKUP($A35,EVENTO!$A$2:$C$4999,3,FALSE),"") -> UFC | D35: IMPRESSORA MONOCROMÁTICO – PÁGINAS A3 | E35: KYOCERA TASKALFA 2554CI + DP-7160 + OCR | F35: 5
A36: 18 | B36: =IFERROR(VLOOKUP($A36,EVENTO!$A$2:$C$4999,2,FALSE),"") -> CADASTRO | C36: =IFERROR(VLOOKUP($A36,EVENTO!$A$2:$C$4999,3,FALSE),"") -> IFCE CAMOCIM | D36: IMPRESSORA MONOCROMÁTICO – PÁGINAS A4 | E36: KYOCERA ECOSYSMA5500ifx + OCR | F36: 3
A37: 18 | B37: =IFERROR(VLOOKUP($A37,EVENTO!$A$2:$C$4999,2,FALSE),"") -> CADASTRO | C37: =IFERROR(VLOOKUP($A37,EVENTO!$A$2:$C$4999,3,FALSE),"") -> IFCE CAMOCIM | D37: IMPRESSORA POLICROMÁTICO – PÁGINAS – A4 | E37: KYOCERA ECOSYS MA3500cix + OCR | F37: 1
A38: 20 | B38: =IFERROR(VLOOKUP($A38,EVENTO!$A$2:$C$4999,2,FALSE),"") -> CADASTRO | C38: =IFERROR(VLOOKUP($A38,EVENTO!$A$2:$C$4999,3,FALSE),"") -> IFCE CAUCAIA | D38: IMPRESSORA MONOCROMÁTICO – PÁGINAS A4 | E38: KYOCERA ECOSYSMA5500ifx + OCR | F38: 5
... A54: 34 | B54: =IFERROR(VLOOKUP($A54,EVENTO!$A$2:$C$4999,2,FALSE),"") -> CADASTRO | C54: =IFERROR(VLOOKUP($A54,EVENTO!$A$2:$C$4999,3,FALSE),"") -> IFRN CAMPUS NATAL | D54: IMPRESSORA MONOCROMÁTICO – PÁGINAS A3 | E54: KYOCERA TASKALFA 2554CI + DP-7160 + OCR | F54: 1
A55: 36 | B55: =IFERROR(VLOOKUP($A55,EVENTO!$A$2:$C$4999,2,FALSE),"") -> CADASTRO | C55: =IFERROR(VLOOKUP($A55,EVENTO!$A$2:$C$4999,3,FALSE),"") -> TRE RJ | D55: MULTIFUNCIONAL POLICROMÁTICA | E55: Kyocera Ecosys MA4000cix | F55: 60 | G55: 224.93
A56: 36 | B56: =IFERROR(VLOOKUP($A56,EVENTO!$A$2:$C$4999,2,FALSE),"") -> CADASTRO | C56: =IFERROR(VLOOKUP($A56,EVENTO!$A$2:$C$4999,3,FALSE),"") -> TRE RJ | D56: IMPRESSORA MONOCROMÁTICA | E56: kyocera Ecosys P2235dn | F56: 110 | G56: 203.94
A57: 36 | B57: =IFERROR(VLOOKUP($A57,EVENTO!$A$2:$C$4999,2,FALSE),"") -> CADASTRO | C57: =IFERROR(VLOOKUP($A57,EVENTO!$A$2:$C$4999,3,FALSE),"") -> TRE RJ | D57: IMPRESSORA POLICROMÁTICA | E57: Kyocera TASKalfa 3554ci | F57: 4 | G57: 763.6
...

Sheet SERVICOS
A1: EVENTO | B1: TIPO_EVENTO | C1: CONTRATO | D1: ITEM | E1: APELIDO | F1: DESCRICAO | G1: QUANTIDADE | H1: VALOR_UNITARIO
A2: 8 | B2: =IFERROR(VLOOKUP($A2,EVENTO!$A$2:$C$4999,2,FALSE),"") -> CADASTRO | C2: =IFERROR(VLOOKUP($A2,EVENTO!$A$2:$C$4999,3,FALSE),"") -> 10a REGIAO MILITAR | D2: IMPRESSORA MONOCROMÁTICO – PÁGINAS A4 | E2: OUTSOURCING DE IMPRESSÃO MONOCROMÁTICO – PÁGINAS A4 | F2: DENTRO DA FRANQUIA SEM PAPEL | G2: 47000 | H2: 0.049
A3: 8 | B3: =IFERROR(VLOOKUP($A3,EVENTO!$A$2:$C$4999,2,FALSE),"") -> CADASTRO | C3: =IFERROR(VLOOKUP($A3,EVENTO!$A$2:$C$4999,3,FALSE),"") -> 10a REGIAO MILITAR | D3: IMPRESSORA MONOCROMÁTICO – PÁGINAS A4 | E3: OUTSOURCING DE IMPRESSÃO MONOCROMÁTICO – PÁGINAS A4 | F3: EXCEDENTE A FRANQUIA SEM PAPEL | G3: 3000 | H3: 0.04
A4: 8 | B4: =IFERROR(VLOOKUP($A4,EVENTO!$A$2:$C$4999,2,FALSE),"") -> CADASTRO | C4: =IFERROR(VLOOKUP($A4,EVENTO!$A$2:$C$4999,3,FALSE),"") -> 10a REGIAO MILITAR | D4: IMPRESSORA POLICROMÁTICO – PÁGINAS – A4 | E4: OUTSOURCING DE IMPRESSÃO POLICROMÁTICO – PÁGINAS – A4 | F4: DENTRO DA FRANQUIA SEM PAPEL | G4: 800 | H4: 0.29
A5: 8 | B5: =IFERROR(VLOOKUP($A5,EVENTO!$A$2:$C$4999,2,FALSE),"") -> CADASTRO | C5: =IFERROR(VLOOKUP($A5,EVENTO!$A$2:$C$4999,3,FALSE),"") -> 10a REGIAO MILITAR | D5: IMPRESSORA POLICROMÁTICO – PÁGINAS – A4 | E5: OUTSOURCING DE IMPRESSÃO POLICROMÁTICO – PÁGINAS – A4 | F5: EXCEDENTE A FRANQUIA SEM PAPEL | G5: 200 | H5: 0.19
A6: 8 | B6: =IFERROR(VLOOKUP($A6,EVENTO!$A$2:$C$4999,2,FALSE),"") -> CADASTRO | C6: =IFERROR(VLOOKUP($A6,EVENTO!$A$2:$C$4999,3,FALSE),"") -> 10a REGIAO MILITAR | D6: IMPRESSORA MONOCROMÁTICO – PÁGINAS A3 | E6: OUTSOURCING DE IMPRESSÃO MONOCROMÁTICO – PÁGINAS A3 | F6: DENTRO DA FRANQUIA SEM PAPEL | G6: 800 | H6: 0.16
A7: 8 | B7: =IFERROR(VLOOKUP($A7,EVENTO!$A$2:$C$4999,2,FALSE),"") -> CADASTRO | C7: =IFERROR(VLOOKUP($A7,EVENTO!$A$2:$C$4999,3,FALSE),"") -> 10a REGIAO MILITAR | D7: IMPRESSORA MONOCROMÁTICO – PÁGINAS A3 | E7: OUTSOURCING DE IMPRESSÃO MONOCROMÁTICO – PÁGINAS A3 | F7: EXCEDENTE A FRANQUIA SEM PAPEL | G7: 200 | H7: 0.08
A8: 10 | B8: =IFERROR(VLOOKUP($A8,EVENTO!$A$2:$C$4999,2,FALSE),"") -> CADASTRO | C8: =IFERROR(VLOOKUP($A8,EVENTO!$A$2:$C$4999,3,FALSE),"") -> CMFOR | D8: SERVIÇO DE IMPRESSÃO CORPORATIVA OU OUTSOURCING DE IMPRESSÃO, COM O FORNECIMENTO DE EQUIPAMENTOS | E8: SERVIÇO DE IMPRESSÃO CORPORATIVA OU OUTSOURCING DE IMPRESSÃO, COM O FORNECIMENTO DE EQUIPAMENTOS | F8: SERVIÇO DE IMPRESSÃO CORPORATIVA OU OUTSOURCING DE IMPRESSÃO, COM O FORNECIMENTO DE EQUIPAMENTOS | G8: 98170 | H8: 0.03
A9: 9 | B9: =IFERROR(VLOOKUP($A9,EVENTO!$A$2:$C$4999,2,FALSE),"") -> ADITIVO DE REAJUSTE E PRAZO | C9: =IFERROR(VLOOKUP($A9,EVENTO!$A$2:$C$4999,3,FALSE),"") -> 10a REGIAO MILITAR | E9: OUTSOURCING DE IMPRESSÃO MONOCROMÁTICO – PÁGINAS A4 | F9: DENTRO DA FRANQUIA SEM PAPEL | G9: 47000 | H9: 0.051
A10: 9 | B10: =IFERROR(VLOOKUP($A10,EVENTO!$A$2:$C$4999,2,FALSE),"") -> ADITIVO DE REAJUSTE E PRAZO | C10: =IFERROR(VLOOKUP($A10,EVENTO!$A$2:$C$4999,3,FALSE),"") -> 10a REGIAO MILITAR | E10: OUTSOURCING DE IMPRESSÃO MONOCROMÁTICO – PÁGINAS A4 | F10: EXCEDENTE A FRANQUIA SEM PAPEL | G10: 3000 | H10: 0.041
A11: 9 | B11: =IFERROR(VLOOKUP($A11,EVENTO!$A$2:$C$4999,2,FALSE),"") -> ADITIVO DE REAJUSTE E PRAZO | C11: =IFERROR(VLOOKUP($A11,EVENTO!$A$2:$C$4999,3,FALSE),"") -> 10a REGIAO MILITAR | E11: OUTSOURCING DE IMPRESSÃO POLICROMÁTICO – PÁGINAS – A4 | F11: DENTRO DA FRANQUIA SEM PAPEL | G11: 800 | H11: 0.3
A12: 9 | B12: =IFERROR(VLOOKUP($A12,EVENTO!$A$2:$C$4999,2,FALSE),"") -> ADITIVO DE REAJUSTE E PRAZO | C12: =IFERROR(VLOOKUP($A12,EVENTO!$A$2:$C$4999,3,FALSE),"") -> 10a REGIAO MILITAR | E12: OUTSOURCING DE IMPRESSÃO POLICROMÁTICO – PÁGINAS – A4 | F12: EXCEDENTE A FRANQUIA SEM PAPEL | G12: 200 | H12: 0.19
A13: 9 | B13: =IFERROR(VLOOKUP($A13,EVENTO!$A$2:$C$4999,2,FALSE),"") -> ADITIVO DE REAJUSTE E PRAZO | C13: =IFERROR(VLOOKUP($A13,EVENTO!$A$2:$C$4999,3,FALSE),"") -> 10a REGIAO MILITAR | E13: OUTSOURCING DE IMPRESSÃO MONOCROMÁTICO – PÁGINAS A3 | F13: DENTRO DA FRANQUIA SEM PAPEL | G13: 800 | H13: 0.16
A14: 9 | B14: =IFERROR(VLOOKUP($A14,EVENTO!$A$2:$C$4999,2,FALSE),"") -> ADITIVO DE REAJUSTE E PRAZO | C14: =IFERROR(VLOOKUP($A14,EVENTO!$A$2:$C$4999,3,FALSE),"") -> 10a REGIAO MILITAR | E14: OUTSOURCING DE IMPRESSÃO MONOCROMÁTICO – PÁGINAS A3 | F14: EXCEDENTE A FRANQUIA SEM PAPEL | G14: 200 | H14: 0.083
A15: 11 | B15: =IFERROR(VLOOKUP($A15,EVENTO!$A$2:$C$4999,2,FALSE),"") -> ADITIVO DE REAJUSTE E PRAZO | C15: =IFERROR(VLOOKUP($A15,EVENTO!$A$2:$C$4999,3,FALSE),"") -> CMFOR | E15: SERVIÇO DE IMPRESSÃO CORPORATIVA OU OUTSOURCING DE IMPRESSÃO, COM O FORNECIMENTO DE EQUIPAMENTOS | F15: SERVIÇO DE IMPRESSÃO CORPORATIVA OU OUTSOURCING DE IMPRESSÃO, COM O FORNECIMENTO DE EQUIPAMENTOS | G15: 98170 | H15: 0.0312527
A16: 12 | B16: =IFERROR(VLOOKUP($A16,EVENTO!$A$2:$C$4999,2,FALSE),"") -> ADITIVO DE REAJUSTE E PRAZO | C16: =IFERROR(VLOOKUP($A16,EVENTO!$A$2:$C$4999,3,FALSE),"") -> CMFOR | E16: SERVIÇO DE IMPRESSÃO CORPORATIVA OU OUTSOURCING DE IMPRESSÃO, COM O FORNECIMENTO DE EQUIPAMENTOS | F16: SERVIÇO DE IMPRESSÃO CORPORATIVA OU OUTSOURCING DE IMPRESSÃO, COM O FORNECIMENTO DE EQUIPAMENTOS | G16: 98170 | H16: 0.0331497
A17: 13 | B17: =IFERROR(VLOOKUP($A17,EVENTO!$A$2:$C$4999,2,FALSE),"") -> CADASTRO | C17: =IFERROR(VLOOKUP($A17,EVENTO!$A$2:$C$4999,3,FALSE),"") -> ESCOLA DE APRENDIZEM DE MARINHEIROS DO CEARÁ | D17: IMPRESSORA POLICROMÁTICO – PÁGINAS – A4 | E17: OUTSOURCING DE IMPRESSÃO POLICROMÁTICO – PÁGINAS – A4 | F17: DENTRO DA FRANQUIA SEM PAPEL | G17: 1200 | H17: 0.29
A18: 13 | B18: =IFERROR(VLOOKUP($A18,EVENTO!$A$2:$C$4999,2,FALSE),"") -> CADASTRO | C18: =IFERROR(VLOOKUP($A18,EVENTO!$A$2:$C$4999,3,FALSE),"") -> ESCOLA DE APRENDIZEM DE MARINHEIROS DO CEARÁ | D18: IMPRESSORA POLICROMÁTICO – PÁGINAS – A4 | E18: OUTSOURCING DE IMPRESSÃO POLICROMÁTICO – PÁGINAS – A4 | F18: EXCEDENTE A FRANQUIA SEM PAPEL | G18: 800 | H18: 0.19
A19: 14 | B19: =IFERROR(VLOOKUP($A19,EVENTO!$A$2:$C$4999,2,FALSE),"") -> ADITIVO DE REAJUSTE E PRAZO | C19: =IFERROR(VLOOKUP($A19,EVENTO!$A$2:$C$4999,3,FALSE),"") -> ESCOLA DE APRENDIZEM DE MARINHEIROS DO CEARÁ | E19: OUTSOURCING DE IMPRESSÃO POLICROMÁTICO – PÁGINAS – A4 | F19: DENTRO DA FRANQUIA SEM PAPEL | G19: 1200 | H19: 0.31
A20: 14 | B20: =IFERROR(VLOOKUP($A20,EVENTO!$A$2:$C$4999,2,FALSE),"") -> ADITIVO DE REAJUSTE E PRAZO | C20: =IFERROR(VLOOKUP($A20,EVENTO!$A$2:$C$4999,3,FALSE),"") -> ESCOLA DE APRENDIZEM DE MARINHEIROS DO CEARÁ | E20: OUTSOURCING DE IMPRESSÃO POLICROMÁTICO – PÁGINAS – A4 | F20: EXCEDENTE A FRANQUIA SEM PAPEL | G20: 800 | H20: 0.2
A21: 15 | B21: =IFERROR(VLOOKUP($A21,EVENTO!$A$2:$C$4999,2,FALSE),"") -> CADASTRO | C21: =IFERROR(VLOOKUP($A21,EVENTO!$A$2:$C$4999,3,FALSE),"") -> UFC | D21: IMPRESSORA MONOCROMÁTICO – PÁGINAS A4 | E21: OUTSOURCING DE IMPRESSÃO MONOCROMÁTICO – PÁGINAS A4 | F21: DENTRO DA FRANQUIA SEM PAPEL | G21: 1905840 | H21: 0.049
A22: 15 | B22: =IFERROR(VLOOKUP($A22,EVENTO!$A$2:$C$4999,2,FALSE),"") -> CADASTRO | C22: =IFERROR(VLOOKUP($A22,EVENTO!$A$2:$C$4999,3,FALSE),"") -> UFC | D22: IMPRESSORA MONOCROMÁTICO – PÁGINAS A4 | E22: OUTSOURCING DE IMPRESSÃO MONOCROMÁTICO – PÁGINAS A4 | F22: EXCEDENTE A FRANQUIA SEM PAPEL | G22: 1270560 | H22: 0.04
A23: 15 | B23: =IFERROR(VLOOKUP($A23,EVENTO!$A$2:$C$4999,2,FALSE),"") -> CADASTRO | C23: =IFERROR(VLOOKUP($A23,EVENTO!$A$2:$C$4999,3,FALSE),"") -> UFC | D23: IMPRESSORA POLICROMÁTICO – PÁGINAS – A4 | E23: OUTSOURCING DE IMPRESSÃO POLICROMÁTICO – PÁGINAS – A4 | F23: DENTRO DA FRANQUIA SEM PAPEL | G23: 14400 | H23: 0.29
A24: 15 | B24: =IFERROR(VLOOKUP($A24,EVENTO!$A$2:$C$4999,2,FALSE),"") -> CADASTRO | C24: =IFERROR(VLOOKUP($A24,EVENTO!$A$2:$C$4999,3,FALSE),"") -> UFC | D24: IMPRESSORA POLICROMÁTICO – PÁGINAS – A4 | E24: OUTSOURCING DE IMPRESSÃO POLICROMÁTICO – PÁGINAS – A4 | F24: EXCEDENTE A FRANQUIA SEM PAPEL | G24: 9600 | H24: 0.19
A25: 15 | B25: =IFERROR(VLOOKUP($A25,EVENTO!$A$2:$C$4999,2,FALSE),"") -> CADASTRO | C25: =IFERROR(VLOOKUP($A25,EVENTO!$A$2:$C$4999,3,FALSE),"") -> UFC | D25: IMPRESSORA MONOCROMÁTICO – PÁGINAS A3 | E25: OUTSOURCING DE IMPRESSÃO MONOCROMÁTICO – PÁGINAS A3 | F25: DENTRO DA FRANQUIA SEM PAPEL | G25: 152652 | H25: 0.16
A26: 15 | B26: =IFERROR(VLOOKUP($A26,EVENTO!$A$2:$C$4999,2,FALSE),"") -> CADASTRO | C26: =IFERROR(VLOOKUP($A26,EVENTO!$A$2:$C$4999,3,FALSE),"") -> UFC | D26: IMPRESSORA MONOCROMÁTICO – PÁGINAS A3 | E26: OUTSOURCING DE IMPRESSÃO MONOCROMÁTICO – PÁGINAS A3 | F26: EXCEDENTE A FRANQUIA SEM PAPEL | G26: 101760 | H26: 0.08
A27: 17 | B27: =IFERROR(VLOOKUP($A27,EVENTO!$A$2:$C$4999,2,FALSE),"") -> APOSTILAMENTO | C27: =IFERROR(VLOOKUP($A27,EVENTO!$A$2:$C$4999,3,FALSE),"") -> UFC | E27: OUTSOURCING DE IMPRESSÃO MONOCROMÁTICO – PÁGINAS A4 | F27: DENTRO DA FRANQUIA SEM PAPEL | G27: 1905840 | H27: 0.05134
A28: 17 | B28: =IFERROR(VLOOKUP($A28,EVENTO!$A$2:$C$4999,2,FALSE),"") -> APOSTILAMENTO | C28: =IFERROR(VLOOKUP($A28,EVENTO!$A$2:$C$4999,3,FALSE),"") -> UFC | E28: OUTSOURCING DE IMPRESSÃO MONOCROMÁTICO – PÁGINAS A4 | F28: EXCEDENTE A FRANQUIA SEM PAPEL | G28: 1270560 | H28: 0.04196
A29: 17 | B29: =IFERROR(VLOOKUP($A29,EVENTO!$A$2:$C$4999,2,FALSE),"") -> APOSTILAMENTO | C29: =IFERROR(VLOOKUP($A29,EVENTO!$A$2:$C$4999,3,FALSE),"") -> UFC | E29: OUTSOURCING DE IMPRESSÃO POLICROMÁTICO – PÁGINAS – A4 | F29: DENTRO DA FRANQUIA SEM PAPEL | G29: 14400 | H29: 0.30524
A30: 17 | B30: =IFERROR(VLOOKUP($A30,EVENTO!$A$2:$C$4999,2,FALSE),"") -> APOSTILAMENTO | C30: =IFERROR(VLOOKUP($A30,EVENTO!$A$2:$C$4999,3,FALSE),"") -> UFC | E30: OUTSOURCING DE IMPRESSÃO POLICROMÁTICO – PÁGINAS – A4 | F30: EXCEDENTE A FRANQUIA SEM PAPEL | G30: 9600 | H30: 0.19918
A31: 17 | B31: =IFERROR(VLOOKUP($A31,EVENTO!$A$2:$C$4999,2,FALSE),"") -> APOSTILAMENTO | C31: =IFERROR(VLOOKUP($A31,EVENTO!$A$2:$C$4999,3,FALSE),"") -> UFC | E31: OUTSOURCING DE IMPRESSÃO MONOCROMÁTICO – PÁGINAS A3 | F31: DENTRO DA FRANQUIA SEM PAPEL | G31: 152652 | H31: 0.16773
